2023-09-17 00:20:30,891 -ERROR- File:log.py[Line:48]ï¼šThis is an error message
Traceback (most recent call last):
  File "/Users/eddy/PycharmProjects/DataManagement/utils/log.py", line 46, in <module>
    raise Exception
Exception
